<?xml version="1.0" ?>
<!-- =================================================================================== -->
<!-- |    This document was autogenerated by xacro from /home/brian/dev/flexiv_arm_driver2/test/flexiv_description/urdf/A02L-M.urdf.xacro | -->
<!-- |    EDITING THIS FILE BY HAND IS NOT RECOMMENDED                                 | -->
<!-- =================================================================================== -->
<robot name="?">
  <!-- JOINTS-->
  <joint name="joint1" type="revolute">
    <parent link="base_link"/>
    <child link="link1"/>
    <origin rpy="?" xyz="?"/>
    <axis xyz="?"/>
    <limit effort="?" lower="?" upper="?" velocity="?"/>
    <safety_controller k_position="100.0" k_velocity="40.0" soft_lower_limit="?" soft_upper_limit="?"/>
    <flexiv>
      <mdh_to_rca_coordinate_transform>
        <offset>0</offset>
        <direction>1</direction>
      </mdh_to_rca_coordinate_transform>
    </flexiv>
  </joint>
  <joint name="joint2" type="revolute">
    <parent link="link1"/>
    <child link="link2"/>
    <origin rpy="?" xyz="?"/>
    <axis xyz="?"/>
    <limit effort="?" lower="?" upper="?" velocity="?"/>
    <safety_controller k_position="100.0" k_velocity="40.0" soft_lower_limit="?" soft_upper_limit="?"/>
    <flexiv>
      <mdh_to_rca_coordinate_transform>
        <offset>0</offset>
        <direction>1</direction>
      </mdh_to_rca_coordinate_transform>
    </flexiv>
  </joint>
  <joint name="joint3" type="revolute">
    <parent link="link2"/>
    <child link="link3"/>
    <origin rpy="?" xyz="?"/>
    <axis xyz="?"/>
    <limit effort="?" lower="?" upper="?" velocity="?"/>
    <safety_controller k_position="100.0" k_velocity="40.0" soft_lower_limit="?" soft_upper_limit="?"/>
    <flexiv>
      <mdh_to_rca_coordinate_transform>
        <offset>0</offset>
        <direction>1</direction>
      </mdh_to_rca_coordinate_transform>
    </flexiv>
  </joint>
  <joint name="joint4" type="revolute">
    <parent link="link3"/>
    <child link="link4"/>
    <origin rpy="?" xyz="?"/>
    <axis xyz="?"/>
    <limit effort="?" lower="?" upper="?" velocity="?"/>
    <safety_controller k_position="100.0" k_velocity="40.0" soft_lower_limit="?" soft_upper_limit="?"/>
    <flexiv>
      <mdh_to_rca_coordinate_transform>
        <offset>0</offset>
        <direction>1</direction>
      </mdh_to_rca_coordinate_transform>
    </flexiv>
  </joint>
  <joint name="joint5" type="revolute">
    <parent link="link4"/>
    <child link="link5"/>
    <origin rpy="?" xyz="?"/>
    <axis xyz="?"/>
    <limit effort="?" lower="?" upper="?" velocity="?"/>
    <safety_controller k_position="100.0" k_velocity="40.0" soft_lower_limit="?" soft_upper_limit="?"/>
    <flexiv>
      <mdh_to_rca_coordinate_transform>
        <offset>0</offset>
        <direction>1</direction>
      </mdh_to_rca_coordinate_transform>
    </flexiv>
  </joint>
  <joint name="joint6" type="revolute">
    <parent link="link5"/>
    <child link="link6"/>
    <origin rpy="?" xyz="?"/>
    <axis xyz="?"/>
    <limit effort="?" lower="?" upper="?" velocity="?"/>
    <safety_controller k_position="100.0" k_velocity="40.0" soft_lower_limit="?" soft_upper_limit="?"/>
    <flexiv>
      <mdh_to_rca_coordinate_transform>
        <offset>-1.5707963267948966</offset>
        <direction>1</direction>
      </mdh_to_rca_coordinate_transform>
    </flexiv>
  </joint>
  <joint name="joint7" type="revolute">
    <parent link="link6"/>
    <child link="link7"/>
    <origin rpy="?" xyz="?"/>
    <axis xyz="?"/>
    <limit effort="?" lower="?" upper="?" velocity="?"/>
    <safety_controller k_position="100.0" k_velocity="40.0" soft_lower_limit="?" soft_upper_limit="?"/>
    <flexiv>
      <mdh_to_rca_coordinate_transform>
        <offset>0</offset>
        <direction>1</direction>
      </mdh_to_rca_coordinate_transform>
    </flexiv>
  </joint>
  <joint name="link7_to_flange" type="fixed">
    <parent link="link7"/>
    <child link="flange"/>
    <origin rpy="?" xyz="?"/>
  </joint>
  <!-- LINKS -->
  <link name="base_link">
    <inertial>
      <mass value="?" />
      <origin rpy="0 0 0" xyz="?" />
      <inertia ixx="?" ixy="?" ixz="?" iyy="?" iyz="?" izz="?" />
    </inertial>
    <visual>
      <origin rpy="0 0 0" xyz="0 0 0"/>
      <geometry>
        <mesh filename="?"/>
      </geometry>
    </visual>
    <collision>
      <origin rpy="0 0 0" xyz="0 0 0"/>
      <geometry>
        <mesh filename="?"/>
      </geometry>
    </collision>
  </link>
  <link name="link1">
    <inertial>
      <mass value="?" />
      <origin rpy="0 0 0" xyz="?" />
      <inertia ixx="?" ixy="?" ixz="?" iyy="?" iyz="?" izz="?" />
    </inertial>
    <visual>
      <origin rpy="0 0 0" xyz="0 0 0"/>
      <geometry>
        <mesh filename="?"/>
      </geometry>
    </visual>
    <collision>
      <origin rpy="0 0 0" xyz="0 0 0"/>
      <geometry>
        <mesh filename="?"/>
      </geometry>
    </collision>
  </link>
  <link name="link2">
    <inertial>
      <mass value="?" />
      <origin rpy="0 0 0" xyz="?" />
      <inertia ixx="?" ixy="?" ixz="?" iyy="?" iyz="?" izz="?" />
    </inertial>
    <visual>
      <origin rpy="0 0 0" xyz="0 0 0"/>
      <geometry>
        <mesh filename="?"/>
      </geometry>
    </visual>
    <collision>
      <origin rpy="0 0 0" xyz="0 0 0"/>
      <geometry>
       <mesh filename="?"/>
      </geometry>
    </collision>
  </link>
  <link name="link3">
    <inertial>
      <mass value="?" />
      <origin rpy="0 0 0" xyz="?" />
      <inertia ixx="?" ixy="?" ixz="?" iyy="?" iyz="?" izz="?" />
    </inertial>
    <visual>
      <origin rpy="0 0 0" xyz="0 0 0"/>
      <geometry>
        <mesh filename="?"/>
      </geometry>
    </visual>
    <collision>
      <origin rpy="0 0 0" xyz="0 0 0"/>
      <geometry>
        <mesh filename="?"/>
      </geometry>
    </collision>
  </link>
  <link name="link4">
    <inertial>
      <mass value="?" />
      <origin rpy="0 0 0" xyz="?" />
      <inertia ixx="?" ixy="?" ixz="?" iyy="?" iyz="?" izz="?" />
    </inertial>
    <visual>
      <origin rpy="0 0 0" xyz="0 0 0"/>
      <geometry>
        <mesh filename="?"/>
      </geometry>
    </visual>
    <collision>
      <origin rpy="0 0 0" xyz="0 0 0"/>
      <geometry>
        <mesh filename="?"/>
      </geometry>
    </collision>
  </link>
  <link name="link5">
    <inertial>
      <mass value="?" />
      <origin rpy="0 0 0" xyz="?" />
      <inertia ixx="?" ixy="?" ixz="?" iyy="?" iyz="?" izz="?" />
    </inertial>
    <visual>
      <origin rpy="0 0 0" xyz="0 0 0"/>
      <geometry>
        <mesh filename="?"/>
      </geometry>
    </visual>
    <collision>
      <origin rpy="0 0 0" xyz="0 0 0"/>
      <geometry>
        <mesh filename="?"/>
      </geometry>
    </collision>
  </link>
  <link name="link6">
    <inertial>
      <mass value="?" />
      <origin rpy="0 0 0" xyz="?" />
      <inertia ixx="?" ixy="?" ixz="?" iyy="?" iyz="?" izz="?" />
    </inertial>
    <visual>
      <origin rpy="0 0 0" xyz="0 0 0"/>
      <geometry>
        <mesh filename="?"/>
      </geometry>
    </visual>
    <collision>
      <origin rpy="0 0 0" xyz="0 0 0"/>
      <geometry>
        <mesh filename="?"/>
      </geometry>
    </collision>
  </link>
  <link name="link7">
    <inertial>
      <mass value="?" />
      <origin rpy="0 0 0" xyz="?" />
      <inertia ixx="?" ixy="?" ixz="?" iyy="?" iyz="?" izz="?" />
    </inertial>
    <visual>
      <origin rpy="0 0 0" xyz="0 0 0"/>
      <geometry>
        <mesh filename="?"/>
      </geometry>
    </visual>
    <collision>
      <origin rpy="0 0 0" xyz="0 0 0"/>
      <geometry>
        <mesh filename="?"/>
      </geometry>
    </collision>
  </link>
  <link name="flange"/>
  <material name="rizon_blue">
    <color rgba="0. 0. 1. 0.5"/>
  </material>
  <material name="rizon_light_grey">
    <color rgba="0.9 0.9 0.9 1"/>
  </material>
  <material name="rizon_dark_grey">
    <color rgba="0.2 0.2 0.2 1"/>
  </material>
  <material name="rizon_white">
    <color rgba="1 1 1 1"/>
  </material>
</robot>
